Workbook

Sheet 进度表
A1: 序号 | B1: 题号 | C1: 主题 | D1: 题目（中文） | E1: 题目（英文） | F1: 难度 | G1: 备选 | H1: 完成日期 | I1: 看解析? | J1: 盲写通过日期 | K1: 状态 | L1: 卡点笔记
A2: 1 | B2: 217 | C2: 数组与哈希 | D2: 存在重复元素 | E2: Contains Duplicate | F2: Easy | H2: 46302 | K2: 已完成 | L2: 暴力 O(n²) → 哈希表 O(n)：一次遍历里边查边插，不必先全部入表
A3: 2 | B3: 242 | C3: 数组与哈希 | D3: 有效的字母异位词 | E3: Valid Anagram | F3: Easy | H3: 46302 | I3: 是 | K3: 已完成 | L3: 先写成排序 O(n log n)；后在提示下改为 26 字母计数数组 O(n)。坑：array 默认不清零，必须 cnts{}, cntt{}
A4: 3 | B4: 1 | C4: 数组与哈希 | D4: 两数之和 | E4: Two Sum | F4: Easy | H4: 46305 | K4: 已完成
A5: 4 | B5: 49 | C5: 数组与哈希 | D5: 字母异位词分组 | E5: Group Anagrams | F5: Medium | H5: 46302 | I5: 是 | K5: 已完成 | L5: 用「排序后的字符串」当哈希 key 分组；组间/组内顺序任意，判题需归一化后再比较
A6: 5 | B6: 347 | C6: 数组与哈希 | D6: 前 K 个高频元素 | E6: Top K Frequent Elements | F6: Medium | H6: 46303 | K6: 已完成 | L6: 哈希计数 + 桶排序（按频次分桶）可做到 O(n)；用堆则是 O(n log k)
A7: 6 | B7: 238 | C7: 数组与哈希 | D7: 除自身以外数组的乘积 | E7: Product of Array Except Self | F7: Medium | H7: 46303 | K7: 已完成 | L7: 左右前缀积各扫一遍；进阶要求 O(1) 额外空间（用输出数组直接存前缀积）
A8: 7 | B8: 36 | C8: 数组与哈希 | D8: 有效的数独 | E8: Valid Sudoku | F8: Medium | H8: 46303 | K8: 已完成 | L8: 行/列/宫各用一次集合判重（3×9 个集合）；注意宫的编号映射 i/3*3+j/3
A9: 8 | B9: 128 | C9: 数组与哈希 | D9: 最长连续序列 | E9: Longest Consecutive Sequence | F9: Medium | H9: 46304 | K9: 需重刷 | L9: 当前用排序 O(n log n)，不满足题目要求的 O(n)。正解：哈希集合 + 只用「无前驱」的元素当序列起点
A10: 9 | B10: 125 | C10: 双指针 | D10: 验证回文串 | E10: Valid Palindrome | F10: Easy | H10: 46302 | I10: 否 | J10: 46302 | K10: 已完成 | L10: 先清洗成新串（只留字母数字并转小写）再双指针夹逼：清楚好写，但 O(n) 额外空间；最优解是原地双指针跳过非字母数字，空间 O(1)。坑：int right = str.size()-1 在空串时靠无符号下溢截断成 -1 才没事，换成 size_t 会崩，应先挡空串
A11: 10 | B11: 167 | C11: 双指针 | D11: 两数之和 II - 输入有序数组 | E11: Two Sum II - Input Array Is Sorted | F11: Medium | H11: 46305 | I11: 否 | J11: 46305 | K11: 已完成 | L11: 对撞双指针 O(n)/O(1)。技巧：两个指针直接定义为 1-based（index1=1, index2=n），访问时 -1，返回时就不用 +1，从根上避开本题最常见的失分点。两个可改进处：三个独立 if 宜改 else-if 链；无解时会返回两个相同下标，可改成找到即 return、循环外 return {}
A12: 11 | B12: 15 | C12: 双指针 | D12: 三数之和 | E12: 3Sum | F12: Medium | H12: 46303 | K12: 已完成 | L12: 排序 + 固定一数后退化为两数之和；去重必须在「选完当前数之后」做
A13: 12 | B13: 11 | C13: 双指针 | D13: 盛最多水的容器 | E13: Container With Most Water | F13: Medium | H13: 46303 | K13: 已完成 | L13: 对撞双指针；每次移动较短的那一侧（贪心），O(n)
A14: 13 | B14: 42 | C14: 双指针 | D14: 接雨水 | E14: Trapping Rain Water | F14: Hard | H14: 46305 | K14: 已完成
A15: 14 | B15: 121 | C15: 滑动窗口 | D15: 买卖股票的最佳时机 | E15: Best Time to Buy and Sell Stock | F15: Easy | H15: 46306 | K15: 已完成
A16: 15 | B16: 3 | C16: 滑动窗口 | D16: 无重复字符的最长子串 | E16: Longest Substring Without Repeating Characters | F16: Medium | H16: 46303 | K16: 已完成 | L16: 滑动窗口 + 集合；右指针扩张、遇重复则左指针收缩
A17: 16 | B17: 424 | C17: 滑动窗口 | D17: 替换后的最长重复字符 | E17: Longest Repeating Character Replacement | F17: Medium | H17: 46306 | K17: 已完成
A18: 17 | B18: 567 | C18: 滑动窗口 | D18: 字符串的排列 | E18: Permutation in String | F18: Medium | H18: 46306 | K18: 已完成
A19: 18 | B19: 76 | C19: 滑动窗口 | D19: 最小覆盖子串 | E19: Minimum Window Substring | F19: Hard | H19: 46307 | K19: 已完成
A20: 19 | B20: 239 | C20: 滑动窗口 | D20: 滑动窗口最大值 | E20: Sliding Window Maximum | F20: Hard | H20: 46308 | K20: 已完成
A21: 20 | B21: 20 | C21: 栈 | D21: 有效的括号 | E21: Valid Parentheses | F21: Easy | H21: 46301 | K21: 已完成
A22: 21 | B22: 155 | C22: 栈 | D22: 最小栈 | E22: Min Stack | F22: Medium | H22: 46309 | K22: 已完成
A23: 22 | B23: 150 | C23: 栈 | D23: 逆波兰表达式求值 | E23: Evaluate Reverse Polish Notation | F23: Medium | H23: 46309 | K23: 已完成
A24: 23 | B24: 739 | C24: 栈 | D24: 每日温度 | E24: Daily Temperatures | F24: Medium | H24: 46310 | I24: 是 | K24: 已完成 | L24: 参照题解写单调栈，主循环一次写对；末尾多写了 while(st.empty())——漏了 !，空栈 top/pop 是 UB，而且本来就多余（res 已初始化为 0）。教训：加循环前先问「条件何时为真、循环体在那种情况下安全吗」。
A25: 24 | B25: 853 | C25: 栈 | D25: 车队 | E25: Car Fleet | F25: Medium | H25: 46311 | K25: 已完成
A26: 25 | B26: 84 | C26: 栈 | D26: 柱状图中最大的矩形 | E26: Largest Rectangle in Histogram | F26: Hard | H26: 46312 | K26: 已完成 | L26: 骨架（哨兵+弹出结算）写对，但边界取错对象：把被弹的元素当左边界、第一个被弹的当下边界。正确：右边界 = i，左边界 = pop 后的新栈顶。
A27: 26 | B27: 704 | C27: 二分查找 | D27: 二分查找 | E27: Binary Search | F27: Easy | K27: 未开始
A28: 27 | B28: 74 | C28: 二分查找 | D28: 搜索二维矩阵 | E28: Search a 2D Matrix | F28: Medium | K28: 未开始
A29: 28 | B29: 875 | C29: 二分查找 | D29: 爱吃香蕉的珂珂 | E29: Koko Eating Bananas | F29: Medium | K29: 未开始
A30: 29 | B30: 153 | C30: 二分查找 | D30: 寻找旋转排序数组中的最小值 | E30: Find Minimum in Rotated Sorted Array | F30: Medium | K30: 未开始
A31: 30 | B31: 33 | C31: 二分查找 | D31: 搜索旋转排序数组 | E31: Search in Rotated Sorted Array | F31: Medium | K31: 未开始
A32: 31 | B32: 981 | C32: 二分查找 | D32: 基于时间的键值存储 | E32: Time Based Key-Value Store | F32: Medium | G32: 可选 | K32: 未开始
A33: 32 | B33: 4 | C33: 二分查找 | D33: 寻找两个正序数组的中位数 | E33: Median of Two Sorted Arrays | F33: Hard | G33: 可选 | H33: 46303 | K33: 已完成 | L33: 二分切分（cut1/cut2）求中位数，O(log(min(m,n)))；边界处理是难点
A34: 33 | B34: 206 | C34: 链表 | D34: 反转链表 | E34: Reverse Linked List | F34: Easy | K34: 未开始
A35: 34 | B35: 21 | C35: 链表 | D35: 合并两个有序链表 | E35: Merge Two Sorted Lists | F35: Easy | H35: 46303 | K35: 已完成 | L35: 哑结点 + 双指针归并；剩余部分直接接上，不必逐节点拷贝
A36: 35 | B36: 143 | C36: 链表 | D36: 重排链表 | E36: Reorder List | F36: Medium | K36: 未开始
A37: 36 | B37: 19 | C37: 链表 | D37: 删除链表的倒数第 N 个结点 | E37: Remove Nth Node From End of List | F37: Medium | H37: 46303 | K37: 已完成 | L37: 哑结点 + 快慢指针，快指针先走 n+1 步，一次遍历
A38: 37 | B38: 138 | C38: 链表 | D38: 随机链表的复制 | E38: Copy List with Random Pointer | F38: Medium | K38: 未开始
A39: 38 | B39: 2 | C39: 链表 | D39: 两数相加 | E39: Add Two Numbers | F39: Medium | H39: 46303 | K39: 已完成 | L39: 哑结点开新链 + 进位 carry 贯穿循环；注意 l1/l2 为空的收尾与最后一位进位
A40: 39 | B40: 141 | C40: 链表 | D40: 环形链表 | E40: Linked List Cycle | F40: Easy | K40: 未开始
...

Sheet 主题看板
A1: 主题进度看板
A2: （自动统计「进度表」中的状态列）
A4: 主题 | B4: 题数 | C4: Easy | D4: Medium | E4: Hard | F4: 已完成 | G4: 需重刷 | H4: 进度 | I4: 约需学习日
A5: 数组与哈希 | B5: 8 | C5: 3 | D5: 5 | E5: 0 | F5: =COUNTIFS(进度表!$C:$C,$A5,进度表!$K:$K,"已完成") | G5: =COUNTIFS(进度表!$C:$C,$A5,进度表!$K:$K,"需重刷") | H5: =IF($B5=0,0,$F5/$B5) | I5: 6.5
A6: 双指针 | B6: 5 | C6: 1 | D6: 3 | E6: 1 | F6: =COUNTIFS(进度表!$C:$C,$A6,进度表!$K:$K,"已完成") | G6: =COUNTIFS(进度表!$C:$C,$A6,进度表!$K:$K,"需重刷") | H6: =IF($B6=0,0,$F6/$B6) | I6: 5.5
A7: 滑动窗口 | B7: 6 | C7: 1 | D7: 3 | E7: 2 | F7: =COUNTIFS(进度表!$C:$C,$A7,进度表!$K:$K,"已完成") | G7: =COUNTIFS(进度表!$C:$C,$A7,进度表!$K:$K,"需重刷") | H7: =IF($B7=0,0,$F7/$B7) | I7: 7.5
A8: 栈 | B8: 6 | C8: 1 | D8: 4 | E8: 1 | F8: =COUNTIFS(进度表!$C:$C,$A8,进度表!$K:$K,"已完成") | G8: =COUNTIFS(进度表!$C:$C,$A8,进度表!$K:$K,"需重刷") | H8: =IF($B8=0,0,$F8/$B8) | I8: 6.5
A9: 二分查找 | B9: 7 | C9: 1 | D9: 5 | E9: 1 | F9: =COUNTIFS(进度表!$C:$C,$A9,进度表!$K:$K,"已完成") | G9: =COUNTIFS(进度表!$C:$C,$A9,进度表!$K:$K,"需重刷") | H9: =IF($B9=0,0,$F9/$B9) | I9: 7.5
A10: 链表 | B10: 11 | C10: 3 | D10: 6 | E10: 2 | F10: =COUNTIFS(进度表!$C:$C,$A10,进度表!$K:$K,"已完成") | G10: =COUNTIFS(进度表!$C:$C,$A10,进度表!$K:$K,"需重刷") | H10: =IF($B10=0,0,$F10/$B10) | I10: 11.5
A11: 树 | B11: 15 | C11: 6 | D11: 7 | E11: 2 | F11: =COUNTIFS(进度表!$C:$C,$A11,进度表!$K:$K,"已完成") | G11: =COUNTIFS(进度表!$C:$C,$A11,进度表!$K:$K,"需重刷") | H11: =IF($B11=0,0,$F11/$B11) | I11: 14
A12: 字典树 | B12: 3 | C12: 0 | D12: 2 | E12: 1 | F12: =COUNTIFS(进度表!$C:$C,$A12,进度表!$K:$K,"已完成") | G12: =COUNTIFS(进度表!$C:$C,$A12,进度表!$K:$K,"需重刷") | H12: =IF($B12=0,0,$F12/$B12) | I12: 4
A13: 堆与优先队列 | B13: 7 | C13: 2 | D13: 4 | E13: 1 | F13: =COUNTIFS(进度表!$C:$C,$A13,进度表!$K:$K,"已完成") | G13: =COUNTIFS(进度表!$C:$C,$A13,进度表!$K:$K,"需重刷") | H13: =IF($B13=0,0,$F13/$B13) | I13: 7
A14: 回溯 | B14: 9 | C14: 0 | D14: 8 | E14: 1 | F14: =COUNTIFS(进度表!$C:$C,$A14,进度表!$K:$K,"已完成") | G14: =COUNTIFS(进度表!$C:$C,$A14,进度表!$K:$K,"需重刷") | H14: =IF($B14=0,0,$F14/$B14) | I14: 10
A15: 图论 | B15: 8 | C15: 0 | D15: 7 | E15: 1 | F15: =COUNTIFS(进度表!$C:$C,$A15,进度表!$K:$K,"已完成") | G15: =COUNTIFS(进度表!$C:$C,$A15,进度表!$K:$K,"需重刷") | H15: =IF($B15=0,0,$F15/$B15) | I15: 9
A16: 进阶图论 | B16: 6 | C16: 0 | D16: 4 | E16: 2 | F16: =COUNTIFS(进度表!$C:$C,$A16,进度表!$K:$K,"已完成") | G16: =COUNTIFS(进度表!$C:$C,$A16,进度表!$K:$K,"需重刷") | H16: =IF($B16=0,0,$F16/$B16) | I16: 8
... A20: 位运算 | B20: 7 | C20: 5 | D20: 2 | E20: 0 | F20: =COUNTIFS(进度表!$C:$C,$A20,进度表!$K:$K,"已完成") | G20: =COUNTIFS(进度表!$C:$C,$A20,进度表!$K:$K,"需重刷") | H20: =IF($B20=0,0,$F20/$B20) | I20: 4.5
A21: 合计 | B21: =SUM(B5:B20) | C21: =SUM(C5:C20) | D21: =SUM(D5:D20) | E21: =SUM(E5:E20) | F21: =SUM(F5:F20) | G21: =SUM(G5:G20) | H21: =IF(B21=0,0,F21/B21) | I21: =SUM(I5:I20)
A23: 提示：状态列在「进度表」K 列修改，本页自动刷新。

Sheet 节奏参考
A1: 26 周节奏参考（每周 6 天新题 + 1 天复习）
A3: 周次 | B3: 阶段 | C3: 本周主题 | D3: 本周题量 | E3: 复习日重点
A4: 第 1 周 | B4: 阶段 1 · 找回手感 | C4: 数组与哈希 | D4: 约 8 题 | E4: 重做 3Sum 前的所有哈希题，重点练「哈希表存什么」
A5: 第 2 周 | B5: 阶段 1 · 找回手感 | C5: 双指针 | D5: 约 5 题 | E5: 重做 3Sum（排序+去重模板），这是后面很多题的骨架
A6: 第 3 周 | B6: 阶段 1 · 找回手感 | C6: 滑动窗口 | D6: 约 6 题 | E6: 默写滑窗模板，重做 424
A7: 第 4 周 | B7: 阶段 1 · 找回手感 | C7: 栈 | D7: 约 6 题 | E7: 重做 739 单调栈，手写下标入栈顺序
A8: 第 5 周 | B8: 阶段 2 · 结构化思维 | C8: 二分查找 | D8: 约 5 题 | E8: 默写闭区间二分模板，重做 875（二分答案）
A9: 第 6 周 | B9: 阶段 2 · 结构化思维 | C9: 链表 | D9: 约 10 题 | E9: 重做 143 重排链表、141 快慢指针
A10: 第 7 周 | B10: 阶段 2 · 结构化思维 | C10: 树 | D10: 约 15 题 | E10: 重做 98 验证 BST、102 层序，递归四步法各写一遍
A11: 第 8 周 | B11: 阶段 3 · 递归与搜索 | C11: 字典树 | D11: 约 2 题 | E11: 手写 Trie 的 insert/search 两个函数
A12: 第 9 周 | B12: 阶段 3 · 递归与搜索 | C12: 堆与优先队列 | D12: 约 7 题 | E12: 重做 215（堆 vs 快速选择）
A13: 第 10 周 | B13: 阶段 3 · 递归与搜索 | C13: 回溯 | D13: 约 9 题 | E13: 重做 46 全排列、78 子集，模板必须闭眼写出
A14: 第 11 周 | B14: 阶段 4 · 图论 | C14: 图论 | D14: 约 7 题 | E14: 重做 200 岛屿数量、207 课程表（拓扑排序）
... A19: 第 16 周 | B19: 阶段 6 · 收尾 | C19: 位运算 | D19: 约 7 题 | E19: 重做 136、338，复习位运算常用技巧
A21: 剩余周次 | B21: 缓冲 / 重刷周 | C21: 把「需重刷」状态的题全部重做一遍；仍未通过的，用最后一周集中处理
